Workbook

Sheet Project
A1: X - Daily Return [%] | B1: Success? | E1: STATISTICAL TESTS
A2: =Data!G4 -> -0.0020061627 | B2: =IF(A2>0,1,0) -> 0
A3: =Data!G5 -> 0.006736425 | B3: =IF(A3>0,1,0) -> 1 | E3: H0: | F3: =F4 -> p | G3: = | H3: =H4 -> 0.45
A4: =Data!G6 -> -0.011390054 | B4: =IF(A4>0,1,0) -> 0 | E4: H1: | F4: p | G4: > | H4: 0.45 | I4: ⭠ The statistical parameter and the direction of the inequality can be selected using a dropdown list.
A5: =Data!G7 -> 0.0020280442 | B5: =IF(A5>0,1,0) -> 1
A6: =Data!G8 -> -0.024109301 | B6: =IF(A6>0,1,0) -> 0
A7: =Data!G9 -> -0.010340016 | B7: =IF(A7>0,1,0) -> 0 | E7: Te = | F7: =IF(F4="μ",(AVERAGE(A:A)-H4)/_xlfn.STDEV.P(A:A)*COUNT(A:A)*0.5,IF(F4="σ",(2*COUNT(A:A)*_xlfn.VAR.P(A:A)/H4^2)^0.5-(2*COUNT(A:A)-3)^0.5,(SUM(B:B)/COUNT(A:A)-H4)/(H4*(1-H4))^0.5*COUNT(A:A)^0.5)) -> 2.4139148
A8: =Data!G10 -> -0.0047783325 | B8: =IF(A8>0,1,0) -> 0 | E8: p-value = | F8: =IF(G4=">",1-_xlfn.NORM.DIST(F7,0,1,1),IF(G4="<",_xlfn.NORM.DIST(F7,0,1,1),2*(1-_xlfn.NORM.DIST(ABS(F7),0,1,1)))) -> 0.007891076 | G8: =IF(F8>=0.05,"(0)",IF(F8>=0.01,"(★)",IF(F8>=0.001,"(★★)","(★★★)"))) -> (★★)
A9: =Data!G11 -> 0.019674461 | B9: =IF(A9>0,1,0) -> 1
A10: =Data!G12 -> -0.040401353 | B10: =IF(A10>0,1,0) -> 0 | E10: DECISION: | F10: =IF(G8="(0)","No grounds to reject H₀ at any reasonable significance level α.",IF(G8="(★)","Weak suggestion: reject H₀.",IF(G8="(★★)","Weak suggestion: reject H₀.","Reject H₀ and accept H₁ at every reasonable significance level α."))) -> Weak suggestion: reject H₀.
A11: =Data!G13 -> 0.0075341501 | B11: =IF(A11>0,1,0) -> 1
A12: =Data!G14 -> -0.031916102 | B12: =IF(A12>0,1,0) -> 0
A13: =Data!G15 -> 0.0053465802 | B13: =IF(A13>0,1,0) -> 1
A14: =Data!G16 -> -0.00076294082 | B14: =IF(A14>0,1,0) -> 0 | D14: SETS OF RESEARCH HYPOTHESES
A15: =Data!G17 -> -0.0039298996 | B15: =IF(A15>0,1,0) -> 0 | D15: I. FOR μ: | E15: QUESTION: | F15: Is the average daily return of Apple in 2025 greater than 0.05%?
A16: =Data!G18 -> 0.031779671 | B16: =IF(A16>0,1,0) -> 1 | E16: PURPOSE: | F16: An investor expecting a minimum daily return greater than 0.05% wonders whether Apple meets their requirements.
A17: =Data!G19 -> 0.03654321 | B17: =IF(A17>0,1,0) -> 1 | F17: H0: μ = 0,0005 | G17: ⭠ The average daily return equals 0.05%.
A18: =Data!G20 -> 0.0046166105 | B18: =IF(A18>0,1,0) -> 1 | F18: H1: μ > 0,0005 | G18: ⭠ The average daily return is greater than 0.05%.
A19: =Data!G21 -> -0.0073945997 | B19: =IF(A19>0,1,0) -> 0 | F19: p-value = | G19: 0.16373 | H19: (0)
A20: =Data!G22 -> -0.0066928801 | B20: =IF(A20>0,1,0) -> 0 | E20: DECISION: | F20: No grounds to reject H₀ at any reasonable α.
A21: =Data!G23 -> -0.033851628 | B21: =IF(A21>0,1,0) -> 0 | F21: The investor cannot assume that the return will exceed the minimum required threshold.
A22: =Data!G24 -> 0.02100148 | B22: =IF(A22>0,1,0) -> 1
A23: =Data!G25 -> -0.0014109971 | B23: =IF(A23>0,1,0) -> 0 | D23: II. FOR σ: | E23: QUESTION: | F23: Is the daily standard deviation of Apple's returns in 2025 less than 2.5%?
A24: =Data!G26 -> 0.0032235205 | B24: =IF(A24>0,1,0) -> 1 | E24: PURPOSE: | F24: The investor wants low volatility and sets 2.5% as their maximum acceptable daily standard deviation.
A25: =Data!G27 -> -0.023969505 | B25: =IF(A25>0,1,0) -> 0 | F25: H0: σ = 0,025 | G25: ⭠ The daily standard deviation of returns equals 2.5%.
A26: =Data!G28 -> 0.0011870877 | B26: =IF(A26>0,1,0) -> 1 | F26: H1: σ < 0,025 | G26: ⭠ The daily standard deviation of returns is greater than 2.5%.
A27: =Data!G29 -> 0.021831501 | B27: =IF(A27>0,1,0) -> 1 | F27: p-value = | G27: 2.7902243e-05 | H27: (★★★)
A28: =Data!G30 -> 0.018272246 | B28: =IF(A28>0,1,0) -> 1 | E28: DECISION: | F28: Reject H₀ and accept H₁ at every reasonable α.
A29: =Data!G31 -> 0.019676951 | B29: =IF(A29>0,1,0) -> 1 | F29: No grounds to reject the hypothesis that the average daily return equals 0.05%.
A30: =Data!G32 -> 0.012708344 | B30: =IF(A30>0,1,0) -> 1 | F30: Based on the data, the standard deviation of Apple's daily returns is significantly less than 2.5% (p-value < 0.01), suggesting the investment falls within the investor's acceptable risk tolerance.
A31: =Data!G33 -> -0.00053329614 | B31: =IF(A31>0,1,0) -> 0
A32: =Data!G34 -> 0.0016335778 | B32: =IF(A32>0,1,0) -> 1 | D32: III. FOR p: | E32: A "success" is defined as a day with a positive daily return for Apple.
A33: =Data!G35 -> 0.0039256664 | B33: =IF(A33>0,1,0) -> 1 | E33: QUESTION: | F33: In 2025, was Apple's daily return positive on more than 45% of trading days in the sample?
A34: =Data!G36 -> -0.0011428898 | B34: =IF(A34>0,1,0) -> 0 | E34: PURPOSE: | F34: The investor wants to verify whether positive-return days occur more frequently than 45% of all days in the sample, in order to assess the likelihood of a positive return.
A35: =Data!G37 -> 0.0066036541 | B35: =IF(A35>0,1,0) -> 1 | F35: H0: p = 0,45 | G35: ⭠ The daily return was positive on 45% of days in the sample.
A36: =Data!G38 -> -0.0005358687 | B36: =IF(A36>0,1,0) -> 0 | F36: H1: p > 0,45 | G36: ⭠ The daily return was positive on more than 45% of days in the sample.
A37: =Data!G39 -> -0.02703526 | B37: =IF(A37>0,1,0) -> 0 | F37: p-value = | G37: 0.007891076 | H37: (★★)
A38: =Data!G40 -> -0.012732685 | B38: =IF(A38>0,1,0) -> 0 | E38: DECISION: | F38: Weak suggestion: reject H₀.
A39: =Data!G41 -> 0.019129692 | B39: =IF(A39>0,1,0) -> 1 | F39: Moderate evidence to reject H₀ suggests that positive-return days occur more frequently than 45% of all days in the sample, which aligns with the investor's objective.
A40: =Data!G42 -> -0.015750057 | B40: =IF(A40>0,1,0) -> 0
...

Sheet Data
A1: Daily stock quotes of Apple Inc. (AAPL), period 01.01.2025–31.12.2025, downloaded from stooq.com in CSV format.
A2: Date | B2: Open | C2: High | D2: Low | E2: Close | F2: Volume | G2: Daily Return [%] | H2: ⭠ Daily Return [%] calculated using the formula
A3: 45659 | B3: 247.809 | C3: 247.978 | D3: 240.733 | E3: 242.752 | F3: 55992832 | G3: None | H3: ⭠ No previous closing price available
A4: 45660 | B4: 242.265 | C4: 243.081 | D4: 240.801 | E4: 242.265 | F4: 40426127 | G4: =((E4-E3)/E3)*100% -> -0.0020061627
A5: 45663 | B5: 243.21 | C5: 246.215 | D5: 242.105 | E5: 243.897 | F5: 45249300 | G5: =((E5-E4)/E4)*100% -> 0.006736425
A6: 45664 | B6: 241.886 | C6: 244.444 | D6: 240.263 | E6: 241.119 | F6: 41040741 | G6: =((E6-E5)/E5)*100% -> -0.011390054
A7: 45665 | B7: 240.831 | C7: 242.615 | D7: 238.969 | E7: 241.608 | F7: 37799126 | G7: =((E7-E6)/E6)*100% -> 0.0020280442
A8: 45667 | B8: 238.929 | C8: 239.078 | D8: 231.95 | E8: 235.783 | F8: 61989958 | G8: =((E8-E7)/E7)*100% -> -0.024109301
A9: 45670 | B9: 232.479 | C9: 233.614 | D9: 228.685 | E9: 233.345 | F9: 49855192 | G9: =((E9-E8)/E8)*100% -> -0.010340016
A10: 45671 | B10: 233.693 | C10: 235.057 | D10: 231.426 | E10: 232.23 | F10: 39613650 | G10: =((E10-E9)/E9)*100% -> -0.0047783325
A11: 45672 | B11: 233.579 | C11: 237.884 | D11: 233.375 | E11: 236.799 | F11: 40012118 | G11: =((E11-E10)/E10)*100% -> 0.019674461
A12: 45673 | B12: 236.282 | C12: 236.939 | D12: 227.004 | E12: 227.232 | F12: 72083600 | G12: =((E12-E11)/E11)*100% -> -0.040401353
A13: 45674 | B13: 231.069 | C13: 231.244 | D13: 227.452 | E13: 228.944 | F13: 68798056 | G13: =((E13-E12)/E12)*100% -> 0.0075341501
A14: 45678 | B14: 222.992 | C14: 223.409 | D14: 218.392 | E14: 221.637 | F14: 98513977 | G14: =((E14-E13)/E13)*100% -> -0.031916102
A15: 45679 | B15: 218.8 | C15: 223.112 | D15: 218.8 | E15: 222.822 | F15: 64416527 | G15: =((E15-E14)/E14)*100% -> 0.0053465802
... A218: 45972 | B218: 269.81 | C218: 275.91 | D218: 269.8 | E218: 275.25 | F218: 46208318 | G218: =((E218-E217)/E217)*100% -> 0.021601158
A219: 45973 | B219: 275 | C219: 275.73 | D219: 271.7 | E219: 273.47 | F219: 48397982 | G219: =((E219-E218)/E218)*100% -> -0.0064668483
A220: 45974 | B220: 274.11 | C220: 276.699 | D220: 272.09 | E220: 272.95 | F220: 49602794 | G220: =((E220-E219)/E219)*100% -> -0.0019014883
A221: 45975 | B221: 271.05 | C221: 275.96 | D221: 269.6 | E221: 272.41 | F221: 47431331 | G221: =((E221-E220)/E220)*100% -> -0.0019783843
A222: 45978 | B222: 268.815 | C222: 270.49 | D222: 265.73 | E222: 267.46 | F222: 45018260 | G222: =((E222-E221)/E221)*100% -> -0.018171139
A223: 45979 | B223: 269.99 | C223: 270.71 | D223: 265.32 | E223: 267.44 | F223: 45677278 | G223: =((E223-E222)/E222)*100% -> -7.4777537e-05
A224: 45980 | B224: 265.525 | C224: 272.21 | D224: 265.5 | E224: 268.56 | F224: 40424492 | G224: =((E224-E223)/E223)*100% -> 0.0041878552
A225: 45981 | B225: 270.83 | C225: 275.43 | D225: 265.92 | E225: 266.25 | F225: 45823568 | G225: =((E225-E224)/E224)*100% -> -0.0086014298
A226: 45982 | B226: 265.95 | C226: 273.33 | D226: 265.67 | E226: 271.49 | F226: 59030832 | G226: =((E226-E225)/E225)*100% -> 0.019680751
A227: 45985 | B227: 270.9 | C227: 277 | D227: 270.9 | E227: 275.92 | F227: 65585796 | G227: =((E227-E226)/E226)*100% -> 0.01631736
A228: 45986 | B228: 275.27 | C228: 280.38 | D228: 275.25 | E228: 276.97 | F228: 46914220 | G228: =((E228-E227)/E227)*100% -> 0.0038054509
A229: 45987 | B229: 276.96 | C229: 279.53 | D229: 276.63 | E229: 277.55 | F229: 33431423 | G229: =((E229-E228)/E228)*100% -> 0.0020940896
A230: 45989 | B230: 277.26 | C230: 279 | D230: 275.986 | E230: 278.85 | F230: 20135620 | G230: =((E230-E229)/E229)*100% -> 0.0046838407
A231: 45992 | B231: 278.01 | C231: 283.42 | D231: 276.14 | E231: 283.1 | F231: 46587722 | G231: =((E231-E230)/E230)*100% -> 0.015241169
A232: 45993 | B232: 283 | C232: 287.4 | D232: 282.63 | E232: 286.19 | F232: 53669532 | G232: =((E232-E231)/E231)*100% -> 0.010914871
A233: 45994 | B233: 286.2 | C233: 288.62 | D233: 283.3 | E233: 284.15 | F233: 43538687 | G233: =((E233-E232)/E232)*100% -> -0.0071281317
A234: 45995 | B234: 284.095 | C234: 284.73 | D234: 278.59 | E234: 280.7 | F234: 43989056 | G234: =((E234-E233)/E233)*100% -> -0.012141475
A235: 45996 | B235: 280.54 | C235: 281.14 | D235: 278.05 | E235: 278.78 | F235: 47265845 | G235: =((E235-E234)/E234)*100% -> -0.0068400428
A236: 45999 | B236: 278.13 | C236: 279.669 | D236: 276.15 | E236: 277.89 | F236: 38211832 | G236: =((E236-E235)/E235)*100% -> -0.0031924815
A237: 46000 | B237: 278.16 | C237: 280.03 | D237: 276.92 | E237: 277.18 | F237: 32193256 | G237: =((E237-E236)/E236)*100% -> -0.0025549678
A238: 46001 | B238: 277.75 | C238: 279.75 | D238: 276.44 | E238: 278.78 | F238: 33038318 | G238: =((E238-E237)/E237)*100% -> 0.0057724223
A239: 46002 | B239: 279.095 | C239: 279.59 | D239: 273.81 | E239: 278.03 | F239: 33247986 | G239: =((E239-E238)/E238)*100% -> -0.0026902934
A240: 46003 | B240: 277.9 | C240: 279.22 | D240: 276.82 | E240: 278.28 | F240: 39532887 | G240: =((E240-E239)/E239)*100% -> 0.00089918354
A241: 46006 | B241: 280.15 | C241: 280.15 | D241: 272.84 | E241: 274.11 | F241: 50409078 | G241: =((E241-E240)/E240)*100% -> -0.014984907
A242: 46007 | B242: 272.82 | C242: 275.5 | D242: 271.79 | E242: 274.61 | F242: 37648628 | G242: =((E242-E241)/E241)*100% -> 0.0018240852
...
